<robot
  name="rugved_description">
  <gazebo>
  <plugin name="differential_drive_controller" filename="libgazebo_ros_diff_drive.so">

    <!-- Plugin update rate in Hz -->
    <updateRate>${update_rate}</updateRate>

    <!-- Name of left joint, defaults to `left_joint` -->
    <leftJoint>base_link_left_wheel_joint</leftJoint>

    <!-- Name of right joint, defaults to `right_joint` -->
    <rightJoint>base_link_right_wheel_joint</rightJoint>

    <!-- The distance from the center of one wheel to the other, in meters, defaults to 0.34 m -->
    <wheelSeparation>0.5380</wheelSeparation>

    <!-- Diameter of the wheels, in meters, defaults to 0.15 m -->
    <wheelDiameter>0.2410</wheelDiameter>

    <!-- Wheel acceleration, in rad/s^2, defaults to 0.0 rad/s^2 -->
    <wheelAcceleration>1.0</wheelAcceleration>

    <!-- Maximum torque which the wheels can produce, in Nm, defaults to 5 Nm -->
    <wheelTorque>20</wheelTorque>

    <!-- Topic to receive geometry_msgs/Twist message commands, defaults to `cmd_vel` -->
    <commandTopic>cmd_vel</commandTopic>

    <!-- Topic to publish nav_msgs/Odometry messages, defaults to `odom` -->
    <odometryTopic>odom</odometryTopic>

    <!-- Odometry frame, defaults to `odom` -->
    <odometryFrame>odom</odometryFrame>

    <!-- Robot frame to calculate odometry from, defaults to `base_footprint` -->
    <robotBaseFrame>base_footprint</robotBaseFrame>

    <!-- Odometry source, 0 for ENCODER, 1 for WORLD, defaults to WORLD -->
    <odometrySource>1</odometrySource>

    <!-- Set to true to publish transforms for the wheel links, defaults to false -->
    <publishWheelTF>true</publishWheelTF>

    <!-- Set to true to publish transforms for the odometry, defaults to true -->
    <publishOdom>true</publishOdom>

    <!-- Set to true to publish sensor_msgs/JointState on /joint_states for the wheel joints, defaults to false -->
    <publishWheelJointState>true</publishWheelJointState>

    <!-- Set to true to swap right and left wheels, defaults to true -->
    <legacyMode>false</legacyMode>
  	</plugin>
  </gazebo>
  <link
    name="base_link">
    <inertial>
      <origin
        xyz="0.10025 -0.00023509 0.24914"
        rpy="0 0 0" />
      <mass
        value="15.129" />
      <inertia
        ixx="0.93792"
        ixy="6.0247E-05"
        ixz="0.12433"
        iyy="1.0368"
        iyz="-0.00022393"
        izz="1.4369" />
    </inertial>
    <visual>
      <origin
        xyz="0 0 0"
        rpy="0 0 0" />
      <geometry>
        <mesh
          filename="package://rugved_description/meshes/base_link.STL" />
      </geometry>
      <material
        name="">
        <color
          rgba="0.52941 0.54902 0.54902 1" />
      </material>
    </visual>
    <collision>
      <origin
        xyz="0 0 0"
        rpy="0 0 0" />
      <geometry>
        <mesh
          filename="package://rugved_description/meshes/base_link.STL" />
      </geometry>
    </collision>
  </link>
  <link
    name="left_wheel">
    <inertial>
      <origin
        xyz="4.8804E-06 4.0992E-08 -0.030108"
        rpy="0 0 0" />
      <mass
        value="3.4752" />
      <inertia
        ixx="0"
        ixy="0"
        ixz="0"
        iyy="0"
        iyz="0"
        izz="0" />
    </inertial>
    <visual>
      <origin
        xyz="0 0 0"
        rpy="0 0 0" />
      <geometry>
        <mesh
          filename="package://rugved_description/meshes/left_wheel.STL" />
      </geometry>
      <material
        name="">
        <color
          rgba="1 1 0 1" />
      </material>
    </visual>
    <collision>
      <origin
        xyz="0 0 0"
        rpy="0 0 0" />
      <geometry>
        <mesh
          filename="package://rugved_description/meshes/left_wheel.STL" />
      </geometry>
    </collision>
  </link>
  <joint
    name="left_wheel_joint"
    type="revolute">
    <origin
      xyz="0.19629 -0.32301 0.17667"
      rpy="-1.5708 -0.25912 -0.00040556" />
    <parent
      link="base_link" />
    <child
      link="left_wheel" />
    <axis
      xyz="0 0 -1" />
    <limit
      lower="0"
      upper="6.29"
      effort="1000"
      velocity="1" />
  </joint>
  <link
    name="right_wheel">
    <inertial>
      <origin
        xyz="4.8804E-06 4.0992E-08 -0.030108"
        rpy="0 0 0" />
      <mass
        value="3.4752" />
      <inertia
        ixx="0"
        ixy="0"
        ixz="0"
        iyy="0"
        iyz="0"
        izz="0" />
    </inertial>
    <visual>
      <origin
        xyz="0 0 0"
        rpy="0 0 0" />
      <geometry>
        <mesh
          filename="package://rugved_description/meshes/right_wheel.STL" />
      </geometry>
      <material
        name="">
        <color
          rgba="1 1 0 1" />
      </material>
    </visual>
    <collision>
      <origin
        xyz="0 0 0"
        rpy="0 0 0" />
      <geometry>
        <mesh
          filename="package://rugved_description/meshes/right_wheel.STL" />
      </geometry>
    </collision>
  </link>
  <joint
    name="right_wheel_joint"
    type="revolute">
    <origin
      xyz="0.19655 0.32239 0.17667"
      rpy="1.5708 -0.034643 -0.00040556" />
    <parent
      link="base_link" />
    <child
      link="right_wheel" />
    <axis
      xyz="0 0 1" />
    <limit
      lower="0"
      upper="6.29"
      effort="1000"
      velocity="1" />
  </joint>
  <link
    name="castor_cover">
    <inertial>
      <origin
        xyz="-5.3158E-06 0.04242 7.9919E-08"
        rpy="0 0 0" />
      <mass
        value="0.050568" />
      <inertia
        ixx="0"
        ixy="0"
        ixz="0"
        iyy="0"
        iyz="0"
        izz="0" />
    </inertial>
    <visual>
      <origin
        xyz="0 0 0"
        rpy="0 0 0" />
      <geometry>
        <mesh
          filename="package://rugved_description/meshes/castor_cover.STL" />
      </geometry>
      <material
        name="">
        <color
          rgba="0.79216 0.81961 0.93333 1" />
      </material>
    </visual>
    <collision>
      <origin
        xyz="0 0 0"
        rpy="0 0 0" />
      <geometry>
        <mesh
          filename="package://rugved_description/meshes/castor_cover.STL" />
      </geometry>
    </collision>
  </link>
  <joint
    name="vertical_castor_joint"
    type="revolute">
    <origin
      xyz="-0.56553 0 0.049371"
      rpy="1.5704 -1.7164E-05 1.5268" />
    <parent
      link="base_link" />
    <child
      link="castor_cover" />
    <axis
      xyz="0 1 0" />
    <limit
      lower="0"
      upper="6.29"
      effort="400"
      velocity="1" />
  </joint>
  <link
    name="castor_wheel">
    <inertial>
      <origin
        xyz="3.785E-08 -6.6349E-08 4.9622E-06"
        rpy="0 0 0" />
      <mass
        value="0.66966" />
      <inertia
        ixx="0"
        ixy="0"
        ixz="0"
        iyy="0"
        iyz="0"
        izz="0" />
    </inertial>
    <visual>
      <origin
        xyz="0 0 0"
        rpy="0 0 0" />
      <geometry>
        <mesh
          filename="package://rugved_description/meshes/castor_wheel.STL" />
      </geometry>
      <material
        name="">
        <color
          rgba="1 1 1 1" />
      </material>
    </visual>
    <collision>
      <origin
        xyz="0 0 0"
        rpy="0 0 0" />
      <geometry>
        <mesh
          filename="package://rugved_description/meshes/castor_wheel.STL" />
      </geometry>
    </collision>
  </link>
  <joint
    name="horizontal_castor_joint"
    type="revolute">
    <origin
      xyz="0 0.013 0"
      rpy="1.5708 0.97377 -1.5708" />
    <parent
      link="castor_cover" />
    <child
      link="castor_wheel" />
    <axis
      xyz="0 0 1" />
    <limit
      lower="0"
      upper="6.29"
      effort="500"
      velocity="1" />
  </joint>
</robot>